[INFO 00:47:02] my_main *******************
[INFO 00:47:02] my_main WANDB RUN ID:
[INFO 00:47:02] my_main a8rpr5mf
[INFO 00:47:02] my_main *******************
[INFO 00:47:03] my_main Beginning training for 3000000 timesteps
[DEBUG 00:47:03] pymarl Stopping Heartbeat
[ERROR 00:47:03] pymarl Failed after 0:00:01!
Traceback (most recent calls WITHOUT Sacred internals):
  File "/home/ubuntu/PERSONAL-DIR/UOA-NEW/final/human-rware/src/main.py", line 44, in my_main
    run(_run, config, _log)
  File "/home/ubuntu/PERSONAL-DIR/UOA-NEW/final/human-rware/src/run.py", line 69, in run
    run_sequential(args=args, logger=logger)
  File "/home/ubuntu/PERSONAL-DIR/UOA-NEW/final/human-rware/src/run.py", line 218, in run_sequential
    episode_batch, expertActions, trainingActions, expert_batch, timesteps, terminated_info= runner.run(test_mode=False)
  File "/home/ubuntu/PERSONAL-DIR/UOA-NEW/final/human-rware/src/runners/parallel_runner.py", line 148, in run
    print(f'at t: {self.t}, k:{self.k}')
AttributeError: 'ParallelRunner' object has no attribute 'k'
